<sdf version='1.6'>
  <world name='default'>
    <model name='physics'>
      <pose frame=''>0 0 0 0 -0 0</pose>
      <static>1</static>
      <link name='body'>
        <collision name='collision'>
          <geometry>
            <mesh>
              <uri>model://physics.dae</uri>
            </mesh>
          </geometry>
          <max_contacts>10</max_contacts>
          <surface>
            <contact>
              <ode/>
            </contact>
            <bounce/>
            <friction>
              <torsional>
                <ode/>
              </torsional>
              <ode/>
            </friction>
          </surface>
        </collision>
        <visual name='visual'>
          <geometry>
            <mesh>
              <uri>model://physics.dae</uri>
            </mesh>
          </geometry>
        </visual>
        <self_collide>0</self_collide>
        <enable_wind>0</enable_wind>
        <kinematic>0</kinematic>
      </link>
    </model>
    <gravity>0 0 -9.8</gravity>
    <magnetic_field>6e-06 2.3e-05 -4.2e-05</magnetic_field>
    <atmosphere type='adiabatic'/>
    <physics name='default_physics' default='0' type='ode'>
      <max_step_size>0.001</max_step_size>
      <real_time_factor>1</real_time_factor>
      <real_time_update_rate>1000</real_time_update_rate>
    </physics>
    <scene>
      <ambient>0.4 0.4 0.4 1</ambient>
      <background>0.7 0.7 0.7 1</background>
      <shadows>1</shadows>
    </scene>
    <audio>
      <device>default</device>
    </audio>
    <wind/>
    <spherical_coordinates>
      <surface_model>EARTH_WGS84</surface_model>
      <latitude_deg>0</latitude_deg>
      <longitude_deg>0</longitude_deg>
      <elevation>0</elevation>
      <heading_deg>0</heading_deg>
    </spherical_coordinates>
    <model name='pluto'>
      <link name='base_footprint'>
        <pose frame=''>0 0 0 0 -0 0</pose>
        <inertial>
          <pose frame=''>0 0 0.2 0 -0 0</pose>
          <mass>40</mass>
          <inertia>
            <ixx>0.447787</ixx>
            <ixy>0</ixy>
            <ixz>-0.143071</ixz>
            <iyy>1.31521</iyy>
            <iyz>0</iyz>
            <izz>1.42809</izz>
          </inertia>
        </inertial>
        <collision name='base_footprint_fixed_joint_lump__base_link_collision'>
          <pose frame=''>0 0 0.2 0 -0.142 0</pose>
          <geometry>
            <mesh>
              <scale>1 1 1</scale>
              <uri>/home/malte/Documents/work/dfki/test_ws/src/pluto_robot/pluto_description/meshes/pluto_base_collision.stl</uri>
            </mesh>
          </geometry>
          <surface>
            <contact>
              <ode/>
            </contact>
            <friction>
              <ode/>
              <torsional>
                <ode/>
              </torsional>
            </friction>
            <bounce/>
          </surface>
          <max_contacts>10</max_contacts>
        </collision>
        <visual name='base_footprint_fixed_joint_lump__base_link_visual'>
          <pose frame=''>0 0 0.2 0 -0.142 0</pose>
          <geometry>
            <mesh>
              <scale>1 1 1</scale>
              <uri>/home/malte/Documents/work/dfki/test_ws/src/pluto_robot/pluto_description/meshes/pluto_base.stl</uri>
            </mesh>
          </geometry>
          <material>
            <script>
              <name>Gazebo/GreyTransparent</name>
              <uri>file://media/materials/scripts/gazebo.material</uri>
            </script>
          </material>
        </visual>
        <visual name='base_footprint_fixed_joint_lump__imu_center_visual_1'>
          <pose frame=''>0.021504 0 0.127312 2.99959 -0 1.5708</pose>
          <geometry>
            <box>
              <size>0.06 0.06 0.02</size>
            </box>
          </geometry>
        </visual>
        <visual name='base_footprint_fixed_joint_lump__velodyne_visual_2'>
          <pose frame=''>0.27709 0 0.307396 0 -0.142 0</pose>
          <geometry>
            <cylinder>
              <length>0.1442</length>
              <radius>0.04265</radius>
            </cylinder>
          </geometry>
          <material>
            <script>
              <uri>__default__</uri>
              <name>__default__</name>
            </script>
          </material>
        </visual>
        <velocity_decay/>
        <gravity>1</gravity>
        <velocity_decay/>
        <sensor name='velodyne' type='ray'>
          <always_on>1</always_on>
          <update_rate>5</update_rate>
          <visualize>0</visualize>
          <ray>
            <scan>
              <horizontal>
                <samples>360</samples>
                <resolution>1</resolution>
                <min_angle>-3.14159</min_angle>
                <max_angle>3.14159</max_angle>
              </horizontal>
              <vertical>
                <samples>3</samples>
                <resolution>1</resolution>
                <min_angle>-0.43284</min_angle>
                <max_angle>0.0349</max_angle>
              </vertical>
            </scan>
            <range>
              <min>0.22</min>
              <max>50</max>
              <resolution>0.02</resolution>
            </range>
          </ray>
          <plugin name='laser_controller' filename='libgazebo_ros_block_laser.so'>
            <frameName>velodyne</frameName>
            <topicName>velodyne</topicName>
            <gaussianNoise>0.02</gaussianNoise>
            <updateRate>5</updateRate>
            <robotNamespace>/</robotNamespace>
          </plugin>
          <pose frame=''>0.264239 0 0.397287 0 -0.142 0</pose>
        </sensor>
        <self_collide>0</self_collide>
        <enable_wind>0</enable_wind>
        <kinematic>0</kinematic>
      </link>
      <link name='left_rear_wheel_link'>
        <pose frame=''>-0.219194 0.19 0.108054 0 -0.142 0</pose>
        <inertial>
          <pose frame=''>0 0 0 1.5708 -0 0</pose>
          <mass>3</mass>
          <inertia>
            <ixx>0.009013</ixx>
            <ixy>0</ixy>
            <ixz>0</ixz>
            <iyy>0.009013</iyy>
            <iyz>0</iyz>
            <izz>0.0159135</izz>
          </inertia>
        </inertial>
        <collision name='left_rear_wheel_link_collision'>
          <pose frame=''>0 0 0 1.5708 -0 0</pose>
          <geometry>
            <cylinder>
              <length>0.065</length>
              <radius>0.103</radius>
            </cylinder>
          </geometry>
          <surface>
            <contact>
              <ode>
                <kp>1e+07</kp>
                <kd>1</kd>
              </ode>
            </contact>
            <friction>
              <ode>
                <mu>1</mu>
                <mu2>1</mu2>
                <fdir1>1 0 0</fdir1>
              </ode>
              <torsional>
                <ode/>
              </torsional>
            </friction>
            <bounce/>
          </surface>
          <max_contacts>10</max_contacts>
        </collision>
        <visual name='left_rear_wheel_link_visual'>
          <pose frame=''>0 0 0 0 -0 0</pose>
          <geometry>
            <mesh>
              <scale>1 1 1</scale>
              <uri>/home/malte/Documents/work/dfki/test_ws/src/pluto_robot/pluto_description/meshes/pluto_wheel.stl</uri>
            </mesh>
          </geometry>
          <material>
            <script>
              <name>Gazebo/DarkGrey</name>
              <uri>file://media/materials/scripts/gazebo.material</uri>
            </script>
          </material>
        </visual>
        <gravity>1</gravity>
        <velocity_decay/>
        <self_collide>0</self_collide>
        <enable_wind>0</enable_wind>
        <kinematic>0</kinematic>
      </link>
      <joint name='left_rear_wheel' type='revolute'>
        <child>left_rear_wheel_link</child>
        <parent>base_footprint</parent>
        <axis>
          <xyz>0 1 0</xyz>
          <limit>
            <lower>-1e+16</lower>
            <upper>1e+16</upper>
          </limit>
          <dynamics>
            <spring_reference>0</spring_reference>
            <spring_stiffness>0</spring_stiffness>
          </dynamics>
          <use_parent_model_frame>1</use_parent_model_frame>
        </axis>
      </joint>
      <link name='right_rear_wheel_link'>
        <pose frame=''>-0.219194 -0.19 0.108054 0 -0.142 0</pose>
        <inertial>
          <pose frame=''>0 0 0 1.5708 -0 0</pose>
          <mass>3</mass>
          <inertia>
            <ixx>0.009013</ixx>
            <ixy>0</ixy>
            <ixz>0</ixz>
            <iyy>0.009013</iyy>
            <iyz>0</iyz>
            <izz>0.0159135</izz>
          </inertia>
        </inertial>
        <collision name='right_rear_wheel_link_collision'>
          <pose frame=''>0 0 0 1.5708 -0 0</pose>
          <geometry>
            <cylinder>
              <length>0.065</length>
              <radius>0.103</radius>
            </cylinder>
          </geometry>
          <surface>
            <contact>
              <ode>
                <kp>1e+07</kp>
                <kd>1</kd>
              </ode>
            </contact>
            <friction>
              <ode>
                <mu>1</mu>
                <mu2>1</mu2>
                <fdir1>1 0 0</fdir1>
              </ode>
              <torsional>
                <ode/>
              </torsional>
            </friction>
            <bounce/>
          </surface>
          <max_contacts>10</max_contacts>
        </collision>
        <visual name='right_rear_wheel_link_visual'>
          <pose frame=''>0 0 0 0 -0 0</pose>
          <geometry>
            <mesh>
              <scale>1 1 1</scale>
              <uri>/home/malte/Documents/work/dfki/test_ws/src/pluto_robot/pluto_description/meshes/pluto_wheel.stl</uri>
            </mesh>
          </geometry>
          <material>
            <script>
              <name>Gazebo/DarkGrey</name>
              <uri>file://media/materials/scripts/gazebo.material</uri>
            </script>
          </material>
        </visual>
        <gravity>1</gravity>
        <velocity_decay/>
        <self_collide>0</self_collide>
        <enable_wind>0</enable_wind>
        <kinematic>0</kinematic>
      </link>
      <joint name='right_rear_wheel' type='revolute'>
        <child>right_rear_wheel_link</child>
        <parent>base_footprint</parent>
        <axis>
          <xyz>0 1 0</xyz>
          <limit>
            <lower>-1e+16</lower>
            <upper>1e+16</upper>
          </limit>
          <dynamics>
            <spring_reference>0</spring_reference>
            <spring_stiffness>0</spring_stiffness>
          </dynamics>
          <use_parent_model_frame>1</use_parent_model_frame>
        </axis>
      </joint>
      <link name='virtual_axis_left'>
        <pose frame=''>0.108621 0.175 0.10441 0 -0 0</pose>
        <inertial>
          <pose frame=''>0 0 0 0 -0 0</pose>
          <mass>0.1</mass>
          <inertia>
            <ixx>8.08333e-05</ixx>
            <ixy>0</ixy>
            <ixz>0</ixz>
            <iyy>0.000657133</iyy>
            <iyz>0</iyz>
            <izz>0.000602966</izz>
          </inertia>
        </inertial>
        <collision name='virtual_axis_left_collision'>
          <pose frame=''>0 0 0 0 -0 -3.14159</pose>
          <geometry>
            <mesh>
              <scale>1 1 1</scale>
              <uri>/home/malte/Documents/work/dfki/test_ws/src/pluto_robot/pluto_description/meshes/pluto_lever_collision.stl</uri>
            </mesh>
          </geometry>
          <surface>
            <contact>
              <ode/>
            </contact>
            <friction>
              <ode/>
              <torsional>
                <ode/>
              </torsional>
            </friction>
            <bounce/>
          </surface>
          <max_contacts>10</max_contacts>
        </collision>
        <visual name='virtual_axis_left_visual'>
          <pose frame=''>0 0 0 0 -0 -3.14159</pose>
          <geometry>
            <mesh>
              <scale>1 1 1</scale>
              <uri>/home/malte/Documents/work/dfki/test_ws/src/pluto_robot/pluto_description/meshes/pluto_lever.stl</uri>
            </mesh>
          </geometry>
          <material>
            <script>
              <name>Gazebo/GreyTransparent</name>
              <uri>file://media/materials/scripts/gazebo.material</uri>
            </script>
          </material>
        </visual>
        <visual name='virtual_axis_left_fixed_joint_lump__imu_left_visual_1'>
          <pose frame=''>0 0 0.2 0 -0 0</pose>
          <geometry>
            <box>
              <size>0.06 0.06 0.02</size>
            </box>
          </geometry>
        </visual>
        <gravity>1</gravity>
        <velocity_decay/>
        <self_collide>0</self_collide>
        <enable_wind>0</enable_wind>
        <kinematic>0</kinematic>
      </link>
      <joint name='virtual_left_to_base_joint' type='revolute'>
        <child>virtual_axis_left</child>
        <parent>base_footprint</parent>
        <axis>
          <xyz>0 1 0</xyz>
          <limit>
            <lower>-0.4</lower>
            <upper>0.4</upper>
            <effort>1000</effort>
            <velocity>10</velocity>
          </limit>
          <dynamics>
            <spring_reference>0</spring_reference>
            <spring_stiffness>0</spring_stiffness>
          </dynamics>
          <use_parent_model_frame>1</use_parent_model_frame>
        </axis>
      </joint>
      <link name='left_front_wheel_link'>
        <pose frame=''>0.216121 0.27 0.10441 0 -0 0</pose>
        <inertial>
          <pose frame=''>0 0 0 1.5708 -0 0</pose>
          <mass>3</mass>
          <inertia>
            <ixx>0.009013</ixx>
            <ixy>0</ixy>
            <ixz>0</ixz>
            <iyy>0.009013</iyy>
            <iyz>0</iyz>
            <izz>0.0159135</izz>
          </inertia>
        </inertial>
        <collision name='left_front_wheel_link_collision'>
          <pose frame=''>0 0 0 1.5708 -0 0</pose>
          <geometry>
            <cylinder>
              <length>0.065</length>
              <radius>0.103</radius>
            </cylinder>
          </geometry>
          <surface>
            <contact>
              <ode>
                <kp>1e+07</kp>
                <kd>1</kd>
              </ode>
            </contact>
            <friction>
              <ode>
                <mu>1</mu>
                <mu2>1</mu2>
                <fdir1>1 0 0</fdir1>
              </ode>
              <torsional>
                <ode/>
              </torsional>
            </friction>
            <bounce/>
          </surface>
          <max_contacts>10</max_contacts>
        </collision>
        <visual name='left_front_wheel_link_visual'>
          <pose frame=''>0 0 0 0 -0 0</pose>
          <geometry>
            <mesh>
              <scale>1 1 1</scale>
              <uri>/home/malte/Documents/work/dfki/test_ws/src/pluto_robot/pluto_description/meshes/pluto_wheel.stl</uri>
            </mesh>
          </geometry>
          <material>
            <script>
              <name>Gazebo/DarkGrey</name>
              <uri>file://media/materials/scripts/gazebo.material</uri>
            </script>
          </material>
        </visual>
        <gravity>1</gravity>
        <velocity_decay/>
        <self_collide>0</self_collide>
        <enable_wind>0</enable_wind>
        <kinematic>0</kinematic>
      </link>
      <joint name='left_front_wheel' type='revolute'>
        <child>left_front_wheel_link</child>
        <parent>virtual_axis_left</parent>
        <axis>
          <xyz>0 1 0</xyz>
          <limit>
            <lower>-1e+16</lower>
            <upper>1e+16</upper>
          </limit>
          <dynamics>
            <spring_reference>0</spring_reference>
            <spring_stiffness>0</spring_stiffness>
          </dynamics>
          <use_parent_model_frame>1</use_parent_model_frame>
        </axis>
      </joint>
      <link name='left_middle_wheel_link'>
        <pose frame=''>0.001121 0.27 0.10441 0 -0 0</pose>
        <inertial>
          <pose frame=''>0 0 0 1.5708 -0 0</pose>
          <mass>3</mass>
          <inertia>
            <ixx>0.009013</ixx>
            <ixy>0</ixy>
            <ixz>0</ixz>
            <iyy>0.009013</iyy>
            <iyz>0</iyz>
            <izz>0.0159135</izz>
          </inertia>
        </inertial>
        <collision name='left_middle_wheel_link_collision'>
          <pose frame=''>0 0 0 1.5708 -0 0</pose>
          <geometry>
            <cylinder>
              <length>0.065</length>
              <radius>0.103</radius>
            </cylinder>
          </geometry>
          <surface>
            <contact>
              <ode>
                <kp>1e+07</kp>
                <kd>1</kd>
              </ode>
            </contact>
            <friction>
              <ode>
                <mu>1</mu>
                <mu2>1</mu2>
                <fdir1>1 0 0</fdir1>
              </ode>
              <torsional>
                <ode/>
              </torsional>
            </friction>
            <bounce/>
          </surface>
          <max_contacts>10</max_contacts>
        </collision>
        <visual name='left_middle_wheel_link_visual'>
          <pose frame=''>0 0 0 0 -0 0</pose>
          <geometry>
            <mesh>
              <scale>1 1 1</scale>
              <uri>/home/malte/Documents/work/dfki/test_ws/src/pluto_robot/pluto_description/meshes/pluto_wheel.stl</uri>
            </mesh>
          </geometry>
          <material>
            <script>
              <name>Gazebo/DarkGrey</name>
              <uri>file://media/materials/scripts/gazebo.material</uri>
            </script>
          </material>
        </visual>
        <gravity>1</gravity>
        <velocity_decay/>
        <self_collide>0</self_collide>
        <enable_wind>0</enable_wind>
        <kinematic>0</kinematic>
      </link>
      <joint name='left_middle_wheel' type='revolute'>
        <child>left_middle_wheel_link</child>
        <parent>virtual_axis_left</parent>
        <axis>
          <xyz>0 1 0</xyz>
          <limit>
            <lower>-1e+16</lower>
            <upper>1e+16</upper>
          </limit>
          <dynamics>
            <spring_reference>0</spring_reference>
            <spring_stiffness>0</spring_stiffness>
          </dynamics>
          <use_parent_model_frame>1</use_parent_model_frame>
        </axis>
      </joint>
      <link name='virtual_axis_right'>
        <pose frame=''>0.108621 -0.175 0.10441 0 -0 0</pose>
        <inertial>
          <pose frame=''>0 0 0 0 -0 0</pose>
          <mass>0.1</mass>
          <inertia>
            <ixx>8.08333e-05</ixx>
            <ixy>0</ixy>
            <ixz>0</ixz>
            <iyy>0.000657133</iyy>
            <iyz>0</iyz>
            <izz>0.000602966</izz>
          </inertia>
        </inertial>
        <collision name='virtual_axis_right_collision'>
          <pose frame=''>0 0 0 0 -0 0</pose>
          <geometry>
            <mesh>
              <scale>1 1 1</scale>
              <uri>/home/malte/Documents/work/dfki/test_ws/src/pluto_robot/pluto_description/meshes/pluto_lever_collision.stl</uri>
            </mesh>
          </geometry>
          <surface>
            <contact>
              <ode/>
            </contact>
            <friction>
              <ode/>
              <torsional>
                <ode/>
              </torsional>
            </friction>
            <bounce/>
          </surface>
          <max_contacts>10</max_contacts>
        </collision>
        <visual name='virtual_axis_right_visual'>
          <pose frame=''>0 0 0 0 -0 0</pose>
          <geometry>
            <mesh>
              <scale>1 1 1</scale>
              <uri>/home/malte/Documents/work/dfki/test_ws/src/pluto_robot/pluto_description/meshes/pluto_lever.stl</uri>
            </mesh>
          </geometry>
          <material>
            <script>
              <name>Gazebo/GreyTransparent</name>
              <uri>file://media/materials/scripts/gazebo.material</uri>
            </script>
          </material>
        </visual>
        <visual name='virtual_axis_right_fixed_joint_lump__imu_right_visual_1'>
          <pose frame=''>0 0 0.2 0 -0 0</pose>
          <geometry>
            <box>
              <size>0.06 0.06 0.02</size>
            </box>
          </geometry>
        </visual>
        <gravity>1</gravity>
        <velocity_decay/>
        <self_collide>0</self_collide>
        <enable_wind>0</enable_wind>
        <kinematic>0</kinematic>
      </link>
      <joint name='virtual_right_to_base_joint' type='revolute'>
        <child>virtual_axis_right</child>
        <parent>base_footprint</parent>
        <axis>
          <xyz>0 1 0</xyz>
          <limit>
            <lower>-0.4</lower>
            <upper>0.4</upper>
            <effort>1000</effort>
            <velocity>10</velocity>
          </limit>
          <dynamics>
            <spring_reference>0</spring_reference>
            <spring_stiffness>0</spring_stiffness>
          </dynamics>
          <use_parent_model_frame>1</use_parent_model_frame>
        </axis>
      </joint>
      <link name='right_front_wheel_link'>
        <pose frame=''>0.216121 -0.27 0.10441 0 -0 0</pose>
        <inertial>
          <pose frame=''>0 0 0 1.5708 -0 0</pose>
          <mass>3</mass>
          <inertia>
            <ixx>0.009013</ixx>
            <ixy>0</ixy>
            <ixz>0</ixz>
            <iyy>0.009013</iyy>
            <iyz>0</iyz>
            <izz>0.0159135</izz>
          </inertia>
        </inertial>
        <collision name='right_front_wheel_link_collision'>
          <pose frame=''>0 0 0 1.5708 -0 0</pose>
          <geometry>
            <cylinder>
              <length>0.065</length>
              <radius>0.103</radius>
            </cylinder>
          </geometry>
          <surface>
            <contact>
              <ode>
                <kp>1e+07</kp>
                <kd>1</kd>
              </ode>
            </contact>
            <friction>
              <ode>
                <mu>1</mu>
                <mu2>1</mu2>
                <fdir1>1 0 0</fdir1>
              </ode>
              <torsional>
                <ode/>
              </torsional>
            </friction>
            <bounce/>
          </surface>
          <max_contacts>10</max_contacts>
        </collision>
        <visual name='right_front_wheel_link_visual'>
          <pose frame=''>0 0 0 0 -0 0</pose>
          <geometry>
            <mesh>
              <scale>1 1 1</scale>
              <uri>/home/malte/Documents/work/dfki/test_ws/src/pluto_robot/pluto_description/meshes/pluto_wheel.stl</uri>
            </mesh>
          </geometry>
          <material>
            <script>
              <name>Gazebo/DarkGrey</name>
              <uri>file://media/materials/scripts/gazebo.material</uri>
            </script>
          </material>
        </visual>
        <gravity>1</gravity>
        <velocity_decay/>
        <self_collide>0</self_collide>
        <enable_wind>0</enable_wind>
        <kinematic>0</kinematic>
      </link>
      <joint name='right_front_wheel' type='revolute'>
        <child>right_front_wheel_link</child>
        <parent>virtual_axis_right</parent>
        <axis>
          <xyz>0 1 0</xyz>
          <limit>
            <lower>-1e+16</lower>
            <upper>1e+16</upper>
          </limit>
          <dynamics>
            <spring_reference>0</spring_reference>
            <spring_stiffness>0</spring_stiffness>
          </dynamics>
          <use_parent_model_frame>1</use_parent_model_frame>
        </axis>
      </joint>
      <link name='right_middle_wheel_link'>
        <pose frame=''>0.001121 -0.27 0.10441 0 -0 0</pose>
        <inertial>
          <pose frame=''>0 0 0 1.5708 -0 0</pose>
          <mass>3</mass>
          <inertia>
            <ixx>0.009013</ixx>
            <ixy>0</ixy>
            <ixz>0</ixz>
            <iyy>0.009013</iyy>
            <iyz>0</iyz>
            <izz>0.0159135</izz>
          </inertia>
        </inertial>
        <collision name='right_middle_wheel_link_collision'>
          <pose frame=''>0 0 0 1.5708 -0 0</pose>
          <geometry>
            <cylinder>
              <length>0.065</length>
              <radius>0.103</radius>
            </cylinder>
          </geometry>
          <surface>
            <contact>
              <ode>
                <kp>1e+07</kp>
                <kd>1</kd>
              </ode>
            </contact>
            <friction>
              <ode>
                <mu>1</mu>
                <mu2>1</mu2>
                <fdir1>1 0 0</fdir1>
              </ode>
              <torsional>
                <ode/>
              </torsional>
            </friction>
            <bounce/>
          </surface>
          <max_contacts>10</max_contacts>
        </collision>
        <visual name='right_middle_wheel_link_visual'>
          <pose frame=''>0 0 0 0 -0 0</pose>
          <geometry>
            <mesh>
              <scale>1 1 1</scale>
              <uri>/home/malte/Documents/work/dfki/test_ws/src/pluto_robot/pluto_description/meshes/pluto_wheel.stl</uri>
            </mesh>
          </geometry>
          <material>
            <script>
              <name>Gazebo/DarkGrey</name>
              <uri>file://media/materials/scripts/gazebo.material</uri>
            </script>
          </material>
        </visual>
        <gravity>1</gravity>
        <velocity_decay/>
        <self_collide>0</self_collide>
        <enable_wind>0</enable_wind>
        <kinematic>0</kinematic>
      </link>
      <joint name='right_middle_wheel' type='revolute'>
        <child>right_middle_wheel_link</child>
        <parent>virtual_axis_right</parent>
        <axis>
          <xyz>0 1 0</xyz>
          <limit>
            <lower>-1e+16</lower>
            <upper>1e+16</upper>
          </limit>
          <dynamics>
            <spring_reference>0</spring_reference>
            <spring_stiffness>0</spring_stiffness>
          </dynamics>
          <use_parent_model_frame>1</use_parent_model_frame>
        </axis>
      </joint>
      <plugin name='imu_controller' filename='libgazebo_ros_imu.so'>
        <alwaysOn>1</alwaysOn>
        <updateRate>100.0</updateRate>
        <topicName>imu/data</topicName>
        <serviceName>/default_imu</serviceName>
        <gaussianNoise>2.89e-08</gaussianNoise>
        <xyzOffsets>0 0 0</xyzOffsets>
        <rpyOffsets>0 0 0</rpyOffsets>
        <ns0:position name='imu_position'/>
        <robotNamespace>/</robotNamespace>
        <bodyName>base_footprint</bodyName>
        <xyzOffset>-0.000275039 0 -0.124198</xyzOffset>
        <rpyOffset>-0.0509122 0.141946 0.0276942</rpyOffset>
      </plugin>
      <plugin name='novatel_gps_sim' filename='libhector_gazebo_ros_gps.so'>
        <frameId>odom_combined</frameId>
        <alwaysOn>1</alwaysOn>
        <updateRate>10.0</updateRate>
        <bodyName>base_footprint</bodyName>
        <topicName>gps/fix</topicName>
        <velocityTopicName>gps/fix_velocity</velocityTopicName>
        <drift>1.0 1.0 1.0</drift>
        <gaussianNoise>0.1 0.1 0.1</gaussianNoise>
        <velocityDrift>0 0 0</velocityDrift>
        <velocityGaussianNoise>0.1 0.1 0.1</velocityGaussianNoise>
        <robotNamespace>/</robotNamespace>
      </plugin>
      <plugin name='base_footprint_controller' filename='libgazebo_ros_p3d.so'>
        <alwaysOn>1</alwaysOn>
        <updateRate>30.0</updateRate>
        <bodyName>base_footprint</bodyName>
        <topicName>gazebo_odom</topicName>
        <gaussianNoise>1.0e-40</gaussianNoise>
        <frameName>map</frameName>
        <ns0:position name='base_footprint_p3d_position_iface'/>
        <robotNamespace>/</robotNamespace>
      </plugin>
      <static>0</static>
      <plugin name='gazebo_ros_control' filename='libgazebo_ros_control.so'>
        <robotNamespace>/</robotNamespace>
      </plugin>
      <pose frame=''>-2.5 0.34 -1.25 0 0 -1.55</pose>
    </model>
    <light name='user_directional_light_0' type='directional'>
      <pose frame=''>5.72138 26.5291 1 0 -0 0</pose>
      <diffuse>0.5 0.5 0.5 1</diffuse>
      <specular>0.1 0.1 0.1 1</specular>
      <direction>0.1 0.1 -0.9</direction>
      <attenuation>
        <range>20</range>
        <constant>0.5</constant>
        <linear>0.01</linear>
        <quadratic>0.001</quadratic>
      </attenuation>
      <cast_shadows>1</cast_shadows>
    </light>
    <light name='user_point_light_0' type='point'>
      <pose frame=''>-12.9819 5.88449 1 0 -0 0</pose>
      <diffuse>0.5 0.5 0.5 1</diffuse>
      <specular>0.1 0.1 0.1 1</specular>
      <attenuation>
        <range>20</range>
        <constant>0.5</constant>
        <linear>0.01</linear>
        <quadratic>0.001</quadratic>
      </attenuation>
      <cast_shadows>0</cast_shadows>
      <direction>0 0 -1</direction>
    </light>
    <light name='user_point_light_1' type='point'>
      <pose frame=''>1.52828 5.47577 1 0 -0 0</pose>
      <diffuse>0.5 0.5 0.5 1</diffuse>
      <specular>0.1 0.1 0.1 1</specular>
      <attenuation>
        <range>20</range>
        <constant>0.5</constant>
        <linear>0.01</linear>
        <quadratic>0.001</quadratic>
      </attenuation>
      <cast_shadows>0</cast_shadows>
      <direction>0 0 -1</direction>
    </light>
    <light name='user_point_light_2' type='point'>
      <pose frame=''>5.67397 1.13395 1 0 -0 0</pose>
      <diffuse>0.5 0.5 0.5 1</diffuse>
      <specular>0.1 0.1 0.1 1</specular>
      <attenuation>
        <range>20</range>
        <constant>0.5</constant>
        <linear>0.01</linear>
        <quadratic>0.001</quadratic>
      </attenuation>
      <cast_shadows>0</cast_shadows>
      <direction>0 0 -1</direction>
    </light>
    <light name='user_point_light_3' type='point'>
      <pose frame=''>5.20805 -13.4499 1 0 -0 0</pose>
      <diffuse>0.5 0.5 0.5 1</diffuse>
      <specular>0.1 0.1 0.1 1</specular>
      <attenuation>
        <range>20</range>
        <constant>0.5</constant>
        <linear>0.01</linear>
        <quadratic>0.001</quadratic>
      </attenuation>
      <cast_shadows>0</cast_shadows>
      <direction>0 0 -1</direction>
    </light>
    <state world_name='default'>
      <sim_time>248 860000000</sim_time>
      <real_time>254 271175166</real_time>
      <wall_time>1590574000 180865589</wall_time>
      <iterations>248860</iterations>
      <model name='physics'>
        <pose frame=''>0 0 0 0 -0 0</pose>
        <scale>1 1 1</scale>
        <link name='body'>
          <pose frame=''>0 0 0 0 -0 0</pose>
          <velocity>0 0 0 0 -0 0</velocity>
          <acceleration>0 0 0 0 -0 0</acceleration>
          <wrench>0 0 0 0 -0 0</wrench>
        </link>
      </model>
      <model name='pluto'>
        <pose frame=''>-3.51286 -0.29763 -1.308 -0.063973 -0.027405 -2.76046</pose>
        <scale>1 1 1</scale>
        <link name='base_footprint'>
          <pose frame=''>-3.51286 -0.29763 -1.308 -0.063973 -0.027405 -2.76046</pose>
          <velocity>-6.9e-05 -0.001431 0.001592 0.000854 0.008499 0.002355</velocity>
          <acceleration>0.182672 -0.276441 0.123098 0.219872 0.470578 0.281914</acceleration>
          <wrench>7.30688 -11.0576 4.92393 0 -0 0</wrench>
        </link>
        <link name='left_front_wheel_link'>
          <pose frame=''>-3.60862 -0.633298 -1.21728 -2.30902 -1.49189 -0.451827</pose>
          <velocity>0.01006 0.000703 -0.004936 -0.071648 -0.130269 0.02034</velocity>
          <acceleration>0.23067 -0.335067 -0.021904 0.128297 0.235965 -0.250322</acceleration>
          <wrench>0.69201 -1.0052 -0.065712 0 -0 0</wrench>
        </link>
        <link name='left_middle_wheel_link'>
          <pose frame=''>-3.40892 -0.553684 -1.21845 -0.81391 1.48724 2.70811</pose>
          <velocity>0.006986 0.013543 0.006034 0.275601 -0.077578 0.120538</velocity>
          <acceleration>0.331982 -0.274653 0.122777 1.59206 0.697041 3.02824</acceleration>
          <wrench>0.995946 -0.82396 0.368331 0 -0 0</wrench>
        </link>
        <link name='left_rear_wheel_link'>
          <pose frame=''>-3.23394 -0.39757 -1.21836 -0.065155 0.198685 -2.77507</pose>
          <velocity>0.000776 -0.000738 -0.000881 0.008331 0.005791 0.000799</velocity>
          <acceleration>0.134876 -0.138902 0.001213 -1.52843 1.56609 -3.09444</acceleration>
          <wrench>0.404629 -0.416705 0.003639 0 -0 0</wrench>
        </link>
        <link name='right_front_wheel_link'>
          <pose frame=''>-3.8082 -0.132904 -1.18105 -2.34161 -1.47017 -0.417675</pose>
          <velocity>0.019755 0.013765 -0.002202 0.016917 -0.089929 -0.044478</velocity>
          <acceleration>0.76057 1.78174 0.072227 -2.95153 -0.781676 -0.739122</acceleration>
          <wrench>2.28171 5.34523 0.216681 0 -0 0</wrench>
        </link>
        <link name='right_middle_wheel_link'>
          <pose frame=''>-3.60876 -0.052806 -1.18481 -2.85943 -1.29964 0.108624</pose>
          <velocity>0.05256 -0.02816 -0.029946 -0.989205 -0.630626 -0.324464</velocity>
          <acceleration>-0.865159 -0.507999 -0.030077 0.058815 0.971515 -0.839626</acceleration>
          <wrench>-2.59548 -1.524 -0.090231 0 -0 0</wrench>
        </link>
        <link name='right_rear_wheel_link'>
          <pose frame=''>-3.37438 -0.04531 -1.19407 -0.119762 1.00652 -2.86356</pose>
          <velocity>3.5e-05 -0.00103 0.000344 0.00619 0.009078 0.004297</velocity>
          <acceleration>0.005878 -0.181326 0.059535 -1.73237 1.42976 -2.42129</acceleration>
          <wrench>0.017634 -0.543979 0.178606 0 -0 0</wrench>
        </link>
        <link name='virtual_axis_left'>
          <pose frame=''>-3.54385 -0.505394 -1.21203 -0.058023 -0.00376 -2.76216</pose>
          <velocity>0.002234 0.001057 0.004138 -0.061982 -0.126482 0.016749</velocity>
          <acceleration>0.283161 -0.375367 0.141709 0.115045 0.102485 -0.391625</acceleration>
          <wrench>0.028316 -0.037537 0.014171 0 -0 0</wrench>
        </link>
        <link name='virtual_axis_right'>
          <pose frame=''>-3.67318 -0.180941 -1.18969 -0.061568 -0.015913 -2.76139</pose>
          <velocity>-0.002287 0.000583 0.000928 0.070166 -0.067418 0.006764</velocity>
          <acceleration>-0.015236 -0.414843 0.37725 -1.03749 0.012228 0.740599</acceleration>
          <wrench>-0.001524 -0.041484 0.037725 0 -0 0</wrench>
        </link>
      </model>
      <light name='user_directional_light_0'>
        <pose frame=''>5.72138 26.5291 1 0 -0 0</pose>
      </light>
      <light name='user_point_light_0'>
        <pose frame=''>-12.9819 5.88449 1 0 -0 0</pose>
      </light>
      <light name='user_point_light_1'>
        <pose frame=''>1.52828 5.47577 1 0 -0 0</pose>
      </light>
      <light name='user_point_light_2'>
        <pose frame=''>5.67397 1.13395 1 0 -0 0</pose>
      </light>
      <light name='user_point_light_3'>
        <pose frame=''>5.20805 -13.4499 1 0 -0 0</pose>
      </light>
    </state>
    <gui fullscreen='0'>
      <camera name='user_camera'>
        <pose frame=''>-14.5696 -29.3984 16.4568 0 0.463642 1.04419</pose>
        <view_controller>orbit</view_controller>
        <projection_type>perspective</projection_type>
      </camera>
    </gui>
  </world>
</sdf>
